Workbook

Sheet Instructions
A1: ITC327W Project Progress and Contribution Workbook
A3: Use this workbook throughout the semester. Update it after each project phase and submit the same workbook again so that progress can be tracked over time.
A5: Sheet | B5: Purpose | D5: Evidence and Accountability Rules
A6: Project Overview | B6: Enter the group and project details. The dashboard summarises task progress automatically. | D6: 1 | E6: Every student must be assigned meaningful work in Microsoft Project.
A7: Task Progress | B7: Record planned and completed tasks, responsible students, dates, status, percentage completed and evidence. | D7: 2 | E7: Completed work must be supported by evidence such as GitHub activity, meeting records, document sections, screenshots or stakeholder communication.
A8: Individual Contributions | B8: Record the work personally completed by each student. Every entry must have evidence. | D8: 3 | E8: GitHub commits are not the only evidence. Planning, interviewing, documentation, coordination and quality review also count.
A9: Stakeholder Engagement | B9: Record meetings, calls and emails with the stakeholder and the main outcomes. | D9: 4 | E9: Do not record work as completed by a student when it was completed by someone else.
A10: Challenges & Actions | B10: Record project challenges, their effect and the corrective action taken. | D10: 5 | E10: Do not place passwords, API keys, identity numbers, private contact details or confidential records in this workbook or on GitHub.
A11: Phase Summary | B11: Provide a short summary of the phase, including achievements, outstanding work and participation concerns. | D11: 6 | E11: The confidential individual peer evaluation must be completed separately on Blackboard.
A12: Group Reflection | B12: Complete one shared reflection after each phase. Be honest and specific.
D13: Recommended Update Points
D14: Unit 1 / Phase 1 | E14: Planning, stakeholder engagement, requirements and initial SRS
D15: Phase 2 | E15: Architecture, UML, ERD and interface design
D16: Phase 3 | E16: Development, integration, testing and demonstration
D17: Final | E17: Overall project summary and final reflection

Sheet Project Overview
A1: Project Overview and Progress Dashboard
A3: Project Information | B3: Group Response | F3: Task Status | G3: Count
A4: Group name or number | B4: Group 4 — Digital Vanguard | F4: Completed | G4: =COUNTIFS('Task Progress'!$B$3:$B$216,$B$8,'Task Progress'!$H$3:$H$216,"Completed") -> 11
A5: Project title | B5: Nama Nameng: A Mobile and Web-Based Ordering, Payment and Queue Management System | F5: In Progress | G5: =COUNTIFS('Task Progress'!$B$3:$B$216,$B$8,'Task Progress'!$H$3:$H$216,"In Progress") -> 0
A6: Stakeholder or organisation | B6: Nama Nameng (Chisa Nyama) — Owner: Doja | F6: Not Started | G6: =COUNTIFS('Task Progress'!$B$3:$B$216,$B$8,'Task Progress'!$H$3:$H$216,"Not Started") -> 0
A7: Group mentor | B7: To be confirmed with module coordinator | F7: Delayed | G7: =COUNTIFS('Task Progress'!$B$3:$B$216,$B$8,'Task Progress'!$H$3:$H$216,"Delayed") -> 0
A8: Reporting phase | B8: Unit 1 / Phase 1 | F8: Blocked | G8: =COUNTIFS('Task Progress'!$B$3:$B$216,$B$8,'Task Progress'!$H$3:$H$216,"Blocked") -> 0
A9: Reporting period | B9: 18 Aug 2026 – 26 Aug 2026 | F9: Overdue | G9: =COUNTIFS('Task Progress'!$B$3:$B$216,$B$8,'Task Progress'!$M$3:$M$216,"Overdue") -> 0
A10: Overall status | B10: Completed
A11: Overall % complete | B11: 1 | F11: Contribution Summary | G11: Count
A12: Main achievement | B12: Completed the project deliverables, including SRS, Microsoft Project Plan, Progress Tracker, Flutter and ASP.NET applications, backend configuration, testing, documentation and GitHub uploads. | F12: Contribution entries | G12: =COUNTIFS('Individual Contributions'!$C$3:$C$316,$B$8,'Individual Contributions'!$E$3:$E$316,"?*") -> 5
A13: Main challenge | B13: Deciding the payment approach — full online payment was descoped to cash-on-collection after feasibility review, which required updating the requirements change log. | F13: Verified entries | G13: =COUNTIFS('Individual Contributions'!$C$3:$C$316,$B$8,'Individual Contributions'!$E$3:$E$316,"?*",'Individual Contributions'!$J$3:$J$316,"Yes") -> 5
A14: Next planned activity | B14: All planned project work is complete; retain final evidence and repository links for submission. | F14: Unverified entries | G14: =COUNTIFS('Individual Contributions'!$C$3:$C$316,$B$8,'Individual Contributions'!$E$3:$E$316,"?*",'Individual Contributions'!$J$3:$J$316,"No") -> 0
F15: Stakeholder engagements | G15: =COUNTIFS('Stakeholder Engagement'!$B$3:$B$216,$B$8,'Stakeholder Engagement'!$A$3:$A$216,">0") -> 2
A18: Phase 2 Snapshot | B18: Group Response | F18: Task Status | G18: Count
A19: Reporting phase | B19: Unit 3 / Phase 2 | F19: Completed | G19: =COUNTIFS('Task Progress'!$B$3:$B$216,$B$19,'Task Progress'!$H$3:$H$216,"Completed") -> 12
A20: Reporting period | B20: 27 Aug 2026 – 23 Sep 2026 | F20: In Progress | G20: =COUNTIFS('Task Progress'!$B$3:$B$216,$B$19,'Task Progress'!$H$3:$H$216,"In Progress") -> 0
A21: Overall status | B21: Completed | F21: Not Started | G21: =COUNTIFS('Task Progress'!$B$3:$B$216,$B$19,'Task Progress'!$H$3:$H$216,"Not Started") -> 0
A22: Overall % complete | B22: 1 | F22: Delayed | G22: =COUNTIFS('Task Progress'!$B$3:$B$216,$B$19,'Task Progress'!$H$3:$H$216,"Delayed") -> 0
A23: Main achievement | B23: Completed system architecture, Use Case Diagram, sequence diagrams, ERD, Flutter and ASP.NET interface prototypes, and Navigation Flow diagram. | F23: Blocked | G23: =COUNTIFS('Task Progress'!$B$3:$B$216,$B$19,'Task Progress'!$H$3:$H$216,"Blocked") -> 0
A24: Main challenge | B24: Phase 2 deliverables completed and checked against project requirements. | F24: Overdue | G24: =COUNTIFS('Task Progress'!$B$3:$B$216,$B$19,'Task Progress'!$M$3:$M$216,"Overdue") -> 0
A25: Next planned activity | B25: All Phase 2 deliverables completed.
F26: Contribution Summary | G26: Count
F27: Contribution entries | G27: =COUNTIFS('Individual Contributions'!$C$3:$C$316,$B$19,'Individual Contributions'!$E$3:$E$316,"?*") -> 11
F28: Verified entries | G28: =COUNTIFS('Individual Contributions'!$C$3:$C$316,$B$19,'Individual Contributions'!$E$3:$E$316,"?*",'Individual Contributions'!$J$3:$J$316,"Yes") -> 11
F29: Unverified entries | G29: =COUNTIFS('Individual Contributions'!$C$3:$C$316,$B$19,'Individual Contributions'!$E$3:$E$316,"?*",'Individual Contributions'!$J$3:$J$316,"No") -> 0
F30: Stakeholder engagements | G30: =COUNTIFS('Stakeholder Engagement'!$B$3:$B$216,$B$19,'Stakeholder Engagement'!$A$3:$A$216,">0") -> 1
A33: Phase 3 Snapshot | B33: Group Response | F33: Task Status | G33: Count
A34: Reporting phase | B34: Phase 3 | F34: Completed | G34: =COUNTIFS('Task Progress'!$B$3:$B$216,$B$34,'Task Progress'!$H$3:$H$216,"Completed") -> 18
A35: Reporting period | B35: 1 Oct 2026 – 30 Oct 2026 | F35: In Progress | G35: =COUNTIFS('Task Progress'!$B$3:$B$216,$B$34,'Task Progress'!$H$3:$H$216,"In Progress") -> 0
A36: Overall status | B36: Completed | F36: Not Started | G36: =COUNTIFS('Task Progress'!$B$3:$B$216,$B$34,'Task Progress'!$H$3:$H$216,"Not Started") -> 0
A37: Overall % complete | B37: 1 | F37: Delayed | G37: =COUNTIFS('Task Progress'!$B$3:$B$216,$B$34,'Task Progress'!$H$3:$H$216,"Delayed") -> 0
A38: Main achievement | B38: Completed the Supabase backend, Flutter customer and staff/manager apps, ASP.NET customer site and staff/manager portal, testing, documentation and project artefacts. | F38: Blocked | G38: =COUNTIFS('Task Progress'!$B$3:$B$216,$B$34,'Task Progress'!$H$3:$H$216,"Blocked") -> 0
A39: Main challenge | B39: Outstanding implementation, security, testing, stakeholder evaluation and documentation tasks have been completed. | F39: Overdue | G39: =COUNTIFS('Task Progress'!$B$3:$B$216,$B$34,'Task Progress'!$M$3:$M$216,"Overdue") -> 0
A40: Next planned activity | B40: All planned project activities are complete; finalise submission using the completed repository and project files.
F42: Contribution Summary | G42: Count
F43: Contribution entries | G43: =COUNTIFS('Individual Contributions'!$C$3:$C$316,$B$34,'Individual Contributions'!$E$3:$E$316,"?*") -> 6
F44: Verified entries | G44: =COUNTIFS('Individual Contributions'!$C$3:$C$316,$B$34,'Individual Contributions'!$E$3:$E$316,"?*",'Individual Contributions'!$J$3:$J$316,"Yes") -> 6
F45: Unverified entries | G45: =COUNTIFS('Individual Contributions'!$C$3:$C$316,$B$34,'Individual Contributions'!$E$3:$E$316,"?*",'Individual Contributions'!$J$3:$J$316,"No") -> 0
F46: Stakeholder engagements | G46: =COUNTIFS('Stakeholder Engagement'!$B$3:$B$216,$B$34,'Stakeholder Engagement'!$A$3:$A$216,">0") -> 0

Sheet GitHub Upload Plan
A1: Simple GitHub Upload Plan
A2: Purpose | B2: Each assigned person uploads their allocated project file to the group GitHub repository. Neo contributed to both codebases but is not assigned a GitHub upload.
A3: Member | B3: What to upload | C3: Suggested repository location / filename | D3: Done? | E3: GitHub link / notes
A4: Lesedi | B4: All Flutter code (customer + staff/manager apps and related Flutter files/tests) | C4: flutter/ (complete Flutter project) | D4: Yes | E4: Completed; uploaded file is available in the group GitHub repository.
A5: Hlayiseka | B5: All ASP.NET code (customer web app + staff/manager portal) | C5: aspnet/ (complete ASP.NET project) | D5: Yes | E5: Completed; uploaded file is available in the group GitHub repository.
A6: Tshepang | B6: Microsoft Project Plan (.mpp) | C6: docs/project-management/NAMA_NAMENG_MANAGEMENT_PLAN.mpp | D6: Yes | E6: Completed; uploaded file is available in the group GitHub repository.
A7: Portia | B7: Software Requirements Specification (SRS) | C7: docs/SRS/ (latest SRS document) | D7: Yes | E7: Completed; uploaded file is available in the group GitHub repository.
A8: Charmaine | B8: Progress Tracker workbook | C8: docs/project-management/ITC327W_Project_Progress_Tracker_2026.xlsx | D8: Yes | E8: Completed; uploaded file is available in the group GitHub repository.
A9: Neo | B9: No GitHub upload assigned | C9: Contributed to both Flutter and ASP.NET code; contribution is acknowledged here. | D9: N/A | E9: Contributed to both codebases; no separate GitHub upload assigned.

Sheet Task Progress
A1: Task Progress Tracker
A2: Task ID | B2: Reporting Phase | C2: Activity | D2: Task Description | E2: Assigned Student(s) | F2: Start Date | G2: Due Date | H2: Status | I2: % Complete | J2: Evidence / Link | K2: Verified by Group | L2: Lecturer Comment | M2: Progress Flag
A3: U1-01 | B3: Unit 1 / Phase 1 | C3: Activity 1.1 | D3: Identify and confirm the external stakeholder | E3: Portia Nkotseng Sefatsa, Charmaine Mogotsi | F3: 46252 | G3: 46255 | H3: Completed | I3: 100 | J3: SRS Appendix A/B — stakeholder identification and confirmation notes | K3: Yes | M3: =IF(D3="","",IF(H3="Completed","Completed",IF(H3="Blocked","Blocked",IF(H3="Delayed","Delayed",IF(AND(G3<>"",G3<TODAY(),H3<>"Completed"),"Overdue","On Track"))))) -> Completed
A4: U1-02 | B4: Unit 1 / Phase 1 | C4: Activity 1.1 | D4: Document the current process and problem | E4: Neo Lekhelebana, Tshepang Morake | F4: 46252 | G4: 46256 | H4: Completed | I4: 100 | J4: SRS Sections 3 & 9 — Problem Statement and Current Process | K4: Yes | M4: =IF(D4="","",IF(H4="Completed","Completed",IF(H4="Blocked","Blocked",IF(H4="Delayed","Delayed",IF(AND(G4<>"",G4<TODAY(),H4<>"Completed"),"Overdue","On Track"))))) -> Completed
A5: U1-03 | B5: Unit 1 / Phase 1 | C5: Activity 1.1 | D5: Define the project aim, objectives and scope | E5: Hlayiseka Matsimbi, Neo Lekhelebana | F5: 46253 | G5: 46256 | H5: Completed | I5: 100 | J5: SRS Sections 4–5 — Aim, Objectives and Scope | K5: Yes | M5: =IF(D5="","",IF(H5="Completed","Completed",IF(H5="Blocked","Blocked",IF(H5="Delayed","Delayed",IF(AND(G5<>"",G5<TODAY(),H5<>"Completed"),"Overdue","On Track"))))) -> Completed
A6: U1-04 | B6: Unit 1 / Phase 1 | C6: Activity 1.2 | D6: Prepare stakeholder interview questions | E6: Portia Nkotseng Sefatsa, Charmaine Mogotsi | F6: 46254 | G6: 46255 | H6: Completed | I6: 100 | J6: SRS Appendix A — interview questions | K6: Yes | M6: =IF(D6="","",IF(H6="Completed","Completed",IF(H6="Blocked","Blocked",IF(H6="Delayed","Delayed",IF(AND(G6<>"",G6<TODAY(),H6<>"Completed"),"Overdue","On Track"))))) -> Completed
A7: U1-05 | B7: Unit 1 / Phase 1 | C7: Activity 1.2 | D7: Conduct and document the stakeholder interview | E7: All Group Members | F7: 46255 | G7: 46257 | H7: Completed | I7: 100 | J7: SRS Appendix A — Interview Notes | K7: Yes | M7: =IF(D7="","",IF(H7="Completed","Completed",IF(H7="Blocked","Blocked",IF(H7="Delayed","Delayed",IF(AND(G7<>"",G7<TODAY(),H7<>"Completed"),"Overdue","On Track"))))) -> Completed
A8: U1-06 | B8: Unit 1 / Phase 1 | C8: Activity 1.3 | D8: Compile the initial SRS | E8: All Group Members | F8: 46255 | G8: 46259 | H8: Completed | I8: 100 | J8: docs/ folder in GitHub repository — SRS document | K8: Yes | M8: =IF(D8="","",IF(H8="Completed","Completed",IF(H8="Blocked","Blocked",IF(H8="Delayed","Delayed",IF(AND(G8<>"",G8<TODAY(),H8<>"Completed"),"Overdue","On Track"))))) -> Completed
A9: U1-07 | B9: Unit 1 / Phase 1 | C9: Activity 1.3 | D9: Create the initial Microsoft Project schedule | E9: Tshepang Morake, Hlayiseka Matsimbi | F9: 46257 | G9: 46258 | H9: Completed | I9: 100 | J9: project-management/ folder in GitHub repository — MS Project file | K9: Yes | M9: =IF(D9="","",IF(H9="Completed","Completed",IF(H9="Blocked","Blocked",IF(H9="Delayed","Delayed",IF(AND(G9<>"",G9<TODAY(),H9<>"Completed"),"Overdue","On Track"))))) -> Completed
A10: U1-08 | B10: Unit 1 / Phase 1 | C10: Activity 1.3 | D10: Create and configure the GitHub repository | E10: Neo Lekhelebana, Charmaine Mogotsi | F10: 46256 | G10: 46257 | H10: Completed | I10: 100 | J10: https://github.com/Lekhelebana/WIL-Project | K10: Yes | M10: =IF(D10="","",IF(H10="Completed","Completed",IF(H10="Blocked","Blocked",IF(H10="Delayed","Delayed",IF(AND(G10<>"",G10<TODAY(),H10<>"Completed"),"Overdue","On Track"))))) -> Completed
A11: U1-09 | B11: Unit 1 / Phase 1 | C11: Activity 1.3 | D11: Create the initial Supabase project | E11: Portia Nkotseng Sefatsa, Tshepang Morake | F11: 46257 | G11: 46258 | H11: Completed | I11: 100 | J11: https://supabase.com/dashboard/project/qmcwfnupigrpkmtommcd | K11: Yes | M11: =IF(D11="","",IF(H11="Completed","Completed",IF(H11="Blocked","Blocked",IF(H11="Delayed","Delayed",IF(AND(G11<>"",G11<TODAY(),H11<>"Completed"),"Overdue","On Track"))))) -> Completed
A12: U1-10 | B12: Unit 1 / Phase 1 | C12: Activity 1.3 | D12: Complete the progress report and contribution record | E12: Hlayiseka Matsimbi | F12: 46258 | G12: 46259 | H12: Completed | I12: 100 | J12: ITC327W_Project_Progress_Tracker_2026.xlsx (this workbook) | K12: Yes | M12: =IF(D12="","",IF(H12="Completed","Completed",IF(H12="Blocked","Blocked",IF(H12="Delayed","Delayed",IF(AND(G12<>"",G12<TODAY(),H12<>"Completed"),"Overdue","On Track"))))) -> Completed
A13: U1-11 | B13: Unit 1 / Phase 1 | C13: Activity 1.3 | D13: Complete the Unit 1 group reflection | E13: All Group Members | F13: 46258 | G13: 46259 | H13: Completed | I13: 100 | J13: Group Reflection sheet (this workbook) | K13: Yes | M13: =IF(D13="","",IF(H13="Completed","Completed",IF(H13="Blocked","Blocked",IF(H13="Delayed","Delayed",IF(AND(G13<>"",G13<TODAY(),H13<>"Completed"),"Overdue","On Track"))))) -> Completed
M14: =IF(D14="","",IF(H14="Completed","Completed",IF(H14="Blocked","Blocked",IF(H14="Delayed","Delayed",IF(AND(G14<>"",G14<TODAY(),H14<>"Completed"),"Overdue","On Track")))))
M15: =IF(D15="","",IF(H15="Completed","Completed",IF(H15="Blocked","Blocked",IF(H15="Delayed","Delayed",IF(AND(G15<>"",G15<TODAY(),H15<>"Completed"),"Overdue","On Track")))))
M16: =IF(D16="","",IF(H16="Completed","Completed",IF(H16="Blocked","Blocked",IF(H16="Delayed","Delayed",IF(AND(G16<>"",G16<TODAY(),H16<>"Completed"),"Overdue","On Track")))))
M17: =IF(D17="","",IF(H17="Completed","Completed",IF(H17="Blocked","Blocked",IF(H17="Delayed","Delayed",IF(AND(G17<>"",G17<TODAY(),H17<>"Completed"),"Overdue","On Track")))))
M18: =IF(D18="","",IF(H18="Completed","Completed",IF(H18="Blocked","Blocked",IF(H18="Delayed","Delayed",IF(AND(G18<>"",G18<TODAY(),H18<>"Completed"),"Overdue","On Track")))))
M19: =IF(D19="","",IF(H19="Completed","Completed",IF(H19="Blocked","Blocked",IF(H19="Delayed","Delayed",IF(AND(G19<>"",G19<TODAY(),H19<>"Completed"),"Overdue","On Track")))))
M20: =IF(D20="","",IF(H20="Completed","Completed",IF(H20="Blocked","Blocked",IF(H20="Delayed","Delayed",IF(AND(G20<>"",G20<TODAY(),H20<>"Completed"),"Overdue","On Track")))))
M21: =IF(D21="","",IF(H21="Completed","Completed",IF(H21="Blocked","Blocked",IF(H21="Delayed","Delayed",IF(AND(G21<>"",G21<TODAY(),H21<>"Completed"),"Overdue","On Track")))))
M22: =IF(D22="","",IF(H22="Completed","Completed",IF(H22="Blocked","Blocked",IF(H22="Delayed","Delayed",IF(AND(G22<>"",G22<TODAY(),H22<>"Completed"),"Overdue","On Track")))))
M23: =IF(D23="","",IF(H23="Completed","Completed",IF(H23="Blocked","Blocked",IF(H23="Delayed","Delayed",IF(AND(G23<>"",G23<TODAY(),H23<>"Completed"),"Overdue","On Track")))))
M24: =IF(D24="","",IF(H24="Completed","Completed",IF(H24="Blocked","Blocked",IF(H24="Delayed","Delayed",IF(AND(G24<>"",G24<TODAY(),H24<>"Completed"),"Overdue","On Track")))))
M25: =IF(D25="","",IF(H25="Completed","Completed",IF(H25="Blocked","Blocked",IF(H25="Delayed","Delayed",IF(AND(G25<>"",G25<TODAY(),H25<>"Completed"),"Overdue","On Track")))))
... M101: =IF(D101="","",IF(H101="Completed","Completed",IF(H101="Blocked","Blocked",IF(H101="Delayed","Delayed",IF(AND(G101<>"",G101<TODAY(),H101<>"Completed"),"Overdue","On Track")))))
A102: U2-01 | B102: Unit 3 / Phase 2 | C102: Activity 2.1 | D102: Design the System Architecture Diagram showing Flutter, ASP.NET and Supabase as one integrated system | E102: Neo Lekhelebana | F102: 46261 | G102: 46264 | H102: Completed | I102: 100 | J102: Nama_Nameng_System_Architecture.drawio | K102: Yes | M102: =IF(D102="","",IF(H102="Completed","Completed",IF(H102="Blocked","Blocked",IF(H102="Delayed","Delayed",IF(AND(G102<>"",G102<TODAY(),H102<>"Completed"),"Overdue","On Track"))))) -> Completed
A103: U2-02 | B103: Unit 3 / Phase 2 | C103: Activity 2.1 | D103: Design the Use Case Diagram (actors, system boundary, include/extend/generalization) | E103: Lesedi Ramolahloane | F103: 46266 | G103: 46270 | H103: Completed | I103: 100 | J103: Nama_Nameng_Use_Case_Diagram.drawio | K103: Yes | M103: =IF(D103="","",IF(H103="Completed","Completed",IF(H103="Blocked","Blocked",IF(H103="Delayed","Delayed",IF(AND(G103<>"",G103<TODAY(),H103<>"Completed"),"Overdue","On Track"))))) -> Completed
A104: U2-03 | B104: Unit 3 / Phase 2 | C104: Activity 2.1 | D104: Design Sequence Diagrams for Guest, Customer, Staff and Manager flows | E104: Portia Nkotseng Sefatsa | F104: 46266 | G104: 46273 | H104: Completed | I104: 100 | J104: 1-Guest / 2-Customer / 3-Staff / 4-Manager sequence diagrams (.drawio/.pdf) | K104: Yes | M104: =IF(D104="","",IF(H104="Completed","Completed",IF(H104="Blocked","Blocked",IF(H104="Delayed","Delayed",IF(AND(G104<>"",G104<TODAY(),H104<>"Completed"),"Overdue","On Track"))))) -> Completed
A105: U2-04 | B105: Unit 3 / Phase 2 | C105: Activity 2.1 | D105: Design the ERD — entities, attributes, PK/FK, relationships and cardinality | E105: Tshepang Morake | F105: 46270 | G105: 46275 | H105: Completed | I105: 100 | J105: ERD.jpeg | K105: Yes | M105: =IF(D105="","",IF(H105="Completed","Completed",IF(H105="Blocked","Blocked",IF(H105="Delayed","Delayed",IF(AND(G105<>"",G105<TODAY(),H105<>"Completed"),"Overdue","On Track"))))) -> Completed
A106: U2-05 | B106: Unit 3 / Phase 2 | C106: Activity 2.1 | D106: Design Supabase row-level security and access control rules per role | E106: Neo Lekhelebana | F106: 46273 | G106: 46277 | H106: Completed | I106: 100 | J106: System Architecture diagram — RLS layer | K106: Yes | M106: =IF(D106="","",IF(H106="Completed","Completed",IF(H106="Blocked","Blocked",IF(H106="Delayed","Delayed",IF(AND(G106<>"",G106<TODAY(),H106<>"Completed"),"Overdue","On Track"))))) -> Completed
A107: U2-06 | B107: Unit 3 / Phase 2 | C107: Activity 2.2 | D107: Prototype Flutter mobile interfaces — customer app and staff/manager app | E107: Charmaine Mogotsi | F107: 46275 | G107: 46283 | H107: Completed | I107: 100 | J107: Final_Flutter_Customer.png, Staff_App.png | K107: Yes | M107: =IF(D107="","",IF(H107="Completed","Completed",IF(H107="Blocked","Blocked",IF(H107="Delayed","Delayed",IF(AND(G107<>"",G107<TODAY(),H107<>"Completed"),"Overdue","On Track"))))) -> Completed
A108: U2-07 | B108: Unit 3 / Phase 2 | C108: Activity 2.2 | D108: Prototype ASP.NET web interfaces — customer web app and staff dashboard | E108: Hlayiseka Matsimbi | F108: 46275 | G108: 46283 | H108: Completed | I108: 100 | J108: Customer_Web_App.png, Nama_Nameng_-_Staff_App_Prototype.png | K108: Yes | M108: =IF(D108="","",IF(H108="Completed","Completed",IF(H108="Blocked","Blocked",IF(H108="Delayed","Delayed",IF(AND(G108<>"",G108<TODAY(),H108<>"Completed"),"Overdue","On Track"))))) -> Completed
A109: U2-08 | B109: Unit 3 / Phase 2 | C109: Activity 2.2 | D109: Design the Navigation Flow diagram across Flutter and ASP.NET screens | E109: Lesedi Ramolahloane | F109: 46284 | G109: 46286 | H109: Completed | I109: 100 | J109: Nama_Nameng_Navigation_Flow.drawio | K109: Yes | M109: =IF(D109="","",IF(H109="Completed","Completed",IF(H109="Blocked","Blocked",IF(H109="Delayed","Delayed",IF(AND(G109<>"",G109<TODAY(),H109<>"Completed"),"Overdue","On Track"))))) -> Completed
A110: U2-09 | B110: Unit 3 / Phase 2 | C110: Activity 2.3 | D110: Review architecture and interface designs with Doja (stakeholder) and log feedback | E110: Portia Nkotseng Sefatsa | F110: 46285 | G110: 46287 | H110: Completed | I110: 100 | J110: SRS Appendix B / D — updated stakeholder evidence | K110: Yes | M110: =IF(D110="","",IF(H110="Completed","Completed",IF(H110="Blocked","Blocked",IF(H110="Delayed","Delayed",IF(AND(G110<>"",G110<TODAY(),H110<>"Completed"),"Overdue","On Track"))))) -> Completed
A111: U2-10 | B111: Unit 3 / Phase 2 | C111: Activity 2.3 | D111: Push design artefacts to GitHub with branch management | E111: Charmaine Mogotsi | F111: 46286 | G111: 46288 | H111: Completed | I111: 100 | J111: github.com/Lekhelebana/WIL-Project | K111: Yes | M111: =IF(D111="","",IF(H111="Completed","Completed",IF(H111="Blocked","Blocked",IF(H111="Delayed","Delayed",IF(AND(G111<>"",G111<TODAY(),H111<>"Completed"),"Overdue","On Track"))))) -> Completed
A112: U2-11 | B112: Unit 3 / Phase 2 | C112: Activity 2.3 | D112: Update Microsoft Project plan for Phase 2 completion and Phase 3 start | E112: Tshepang Morake | F112: 46287 | G112: 46288 | H112: Completed | I112: 100 | J112: NAMA_NAMENG_MANAGEMENT_PLAN.mpp | K112: Yes | M112: =IF(D112="","",IF(H112="Completed","Completed",IF(H112="Blocked","Blocked",IF(H112="Delayed","Delayed",IF(AND(G112<>"",G112<TODAY(),H112<>"Completed"),"Overdue","On Track"))))) -> Completed
A113: U2-12 | B113: Unit 3 / Phase 2 | C113: Activity 2.3 | D113: Complete Phase 2 progress report and group reflection | E113: Hlayiseka Matsimbi | F113: 46288 | G113: 46288 | H113: Completed | I113: 100 | J113: ITC327W_Project_Progress_Tracker_2026.xlsx (this workbook) | K113: Yes | M113: =IF(D113="","",IF(H113="Completed","Completed",IF(H113="Blocked","Blocked",IF(H113="Delayed","Delayed",IF(AND(G113<>"",G113<TODAY(),H113<>"Completed"),"Overdue","On Track"))))) -> Completed
M114: =IF(D114="","",IF(H114="Completed","Completed",IF(H114="Blocked","Blocked",IF(H114="Delayed","Delayed",IF(AND(G114<>"",G114<TODAY(),H114<>"Completed"),"Overdue","On Track")))))
M115: =IF(D115="","",IF(H115="Completed","Completed",IF(H115="Blocked","Blocked",IF(H115="Delayed","Delayed",IF(AND(G115<>"",G115<TODAY(),H115<>"Completed"),"Overdue","On Track")))))
...

Sheet Individual Contributions
A1: Individual Contribution Record
A2: Student Name | B2: Student Number | C2: Reporting Phase | D2: Activity | E2: Assigned Responsibility | F2: Work Personally Completed | G2: Date Completed | H2: Hours Spent | I2: Evidence / Link | J2: Verified by Group | K2: Verification Date | L2: Notes
A3: Neo Lekhelebana | B3: 221000484 | C3: Unit 1 / Phase 1 | D3: -Activity 1.1 -Activity 1.2 -Activity 1.3 | E3: -Create the initial supabase setup -Define the project aim, objectives and scope | F3: Documentation and Supabase setups. | G3: 46252 | H3: 3 | I3: Supabase dashboard (link in Task Progress U1-09); SRS Sections 4–5 | J3: Yes | K3: 46259
A4: Tshepang Morake | B4: 222075924 | C4: Unit 1 / Phase 1 | D4: -Activity 1.1 -Activity 1.3 | E4: -Create initial Supabase setup -Microsoft Project Plan | F4: Microsoft project plan and initial Supabase setup. | G4: 46258 | H4: 2 | I4: project-management/ folder in GitHub repo (MPP file); Supabase dashboard link | J4: Yes | K4: 46259
A5: Portia Nkotseng Sefatsa | B5: 220007164 | C5: Unit 1 / Phase 1 | D5: -Activity 1.1 -Activity 1.2 | E5: -Project Risk Analysis -Create the initial Supabase project | F5: Initial Supabase Setup and project risk analysis. | G5: 46259 | H5: 4 | I5: SRS Project Risk Register section; Supabase dashboard link | J5: Yes | K5: 46259
A6: Charmaine Mogotsi | B6: 221023182 | C6: Unit 1 / Phase 1 | D6: -Activity 1.1 -Activity 1.2 -Activity 1.3 | E6: -Prepare stakeholder interview questions -Create and configure the GitHub repository | F6: configuring the GitHub repository and stakeholder questions preparations. | G6: 46259 | H6: 5 | I6: GitHub repo commit history and README; SRS Appendix A interview questions | J6: Yes | K6: 46259
A7: Hlayiseka Matsimbi | B7: 221027400 | C7: Unit 1 / Phase 1 | D7: -Activity 1.1 -Activity 1.2 -Activity 1.3 | E7: -Complete the progress report and contribution record -Define the project aim, objectives and scope | F7: Project scope triple constraints documentation and progress report contribution. | G7: 46260 | H7: 5 | I7: This workbook (Progress Tracker); SRS Section 5 Project Scope | J7: Yes | K7: 46259
A8: Neo Lekhelebana | B8: 221000484 | C8: Unit 3 / Phase 2 | D8: -Activity 2.1 (U2-01) -Activity 2.1 (U2-05) | E8: -Design the System Architecture Diagram (Flutter, ASP.NET, Supabase) -Design Supabase row-level security and access control rules per role | F8: System architecture diagram and Supabase RLS / access-control design. | G8: 46277 | H8: 6 | I8: Nama_Nameng_System_Architecture.drawio; System Architecture diagram — RLS layer | J8: Yes | K8: 46288
A9: Lesedi Ramolahloane | B9: 219015068 | C9: Unit 3 / Phase 2 | D9: -Activity 2.1 (U2-02) -Activity 2.2 (U2-08) | E9: -Design the Use Case Diagram (actors, system boundary, include/extend/generalization) -Design the Navigation Flow diagram across Flutter and ASP.NET screens | F9: Use case diagram and navigation flow diagrams for the Flutter and ASP.NET screens. | G9: 46286 | H9: 5 | I9: Nama_Nameng_Use_Case_Diagram.drawio; Nama_Nameng_Navigation_Flow.drawio | J9: Yes | K9: 46288
A10: Portia Nkotseng Sefatsa | B10: 220007164 | C10: Unit 3 / Phase 2 | D10: -Activity 2.1 (U2-03) -Activity 2.3 (U2-09) | E10: -Design Sequence Diagrams for Guest, Customer, Staff and Manager flows -Review architecture and interface designs with Doja (stakeholder) and log feedback | F10: Four sequence diagrams (Guest, Customer, Staff, Manager) and the stakeholder design review session with Doja. | G10: 46287 | H10: 6 | I10: 1-Guest / 2-Customer / 3-Staff / 4-Manager sequence diagrams; SRS Section 18.4 Stakeholder Design Review | J10: Yes | K10: 46288
A11: Tshepang Morake | B11: 222075924 | C11: Unit 3 / Phase 2 | D11: -Activity 2.1 (U2-04) -Activity 2.3 (U2-11) | E11: -Design the ERD — entities, attributes, PK/FK, relationships and cardinality -Update Microsoft Project plan for Phase 2 completion and Phase 3 start | F11: Entity Relationship Diagram and the updated Microsoft Project schedule. | G11: 46288 | H11: 5 | I11: ERD.jpeg; NAMA_NAMENG_MANAGEMENT_PLAN.mpp | J11: Yes | K11: 46288
A12: Charmaine Mogotsi | B12: 221023182 | C12: Unit 3 / Phase 2 | D12: -Activity 2.2 (U2-06) -Activity 2.3 (U2-10) | E12: -Prototype Flutter mobile interfaces — customer app and staff/manager app -Push design artefacts to GitHub with branch management | F12: Flutter customer and staff/manager interface prototypes; pushed Phase 2 design artefacts to GitHub. | G12: 46288 | H12: 6 | I12: Final_Flutter_Customer.png, Staff_App.png; github.com/Lekhelebana/WIL-Project | J12: Yes | K12: 46288
A13: Hlayiseka Matsimbi | B13: 221027400 | C13: Unit 3 / Phase 2 | D13: -Activity 2.2 (U2-07) -Activity 2.3 (U2-12) | E13: -Prototype ASP.NET web interfaces — customer web app and staff dashboard -Complete Phase 2 progress report and group reflection | F13: ASP.NET customer and staff dashboard interface prototypes; completed the Phase 2 progress report and group reflection. | G13: 46288 | H13: 6 | I13: Customer_Web_App.png, Nama_Nameng_-_Staff_App_Prototype.png; this workbook (Progress Tracker) | J13: Yes | K13: 46288
A202: Neo Lekhelebana | B202: 221000484 | C202: Unit 3 / Phase 2 | D202: Activity 2.1, 2.3 | E202: System Architecture Diagram; Supabase RLS design; GitHub branch management | F202: Modelled the Flutter/ASP.NET/Supabase architecture in draw.io, defined role-based RLS rules, and organised GitHub branches for design artefacts. | G202: 46277 | H202: 6 | I202: Nama_Nameng_System_Architecture.drawio; GitHub commit history | J202: Yes | K202: 46288 | L202: Second Phase 2 entry for this student; it differs from the earlier entry. Group to confirm which one stands.
A203: Charmaine Mogotsi | B203: 221023182 | C203: Unit 3 / Phase 2 | D203: Activity 2.1, 2.2 | E203: Use Case Diagram; Flutter interface prototyping | F203: Built the Use Case Diagram (actors, include/extend/generalization) and designed the Flutter customer and staff app screens. | G203: 46283 | H203: 7 | I203: Nama_Nameng_Use_Case_Diagram.drawio; Final_Flutter_Customer.png; Staff_App.png | J203: Yes | K203: 46288 | L203: Second Phase 2 entry for this student; it differs from the earlier entry. Group to confirm which one stands.
A204: Portia Nkotseng Sefatsa | B204: 220007164 | C204: Unit 3 / Phase 2 | D204: Activity 2.1, 2.2 | E204: Sequence Diagrams (Guest/Customer); ERD; ASP.NET interface prototyping | F204: Drafted the Guest and Customer sequence diagrams, contributed to the ERD, and designed the ASP.NET customer web screens. | G204: 46283 | H204: 8 | I204: 1-Guest / 2-Customer sequence diagrams; ERD.jpeg; Customer_Web_App.png | J204: Yes | K204: 46288 | L204: Second Phase 2 entry for this student; it differs from the earlier entry. Group to confirm which one stands.
A205: Tshepang Morake | B205: 222075924 | C205: Unit 3 / Phase 2 | D205: Activity 2.1, 2.2, 2.3 | E205: ERD; ASP.NET staff dashboard prototyping; Microsoft Project update | F205: Finalised the ERD cardinalities, designed the ASP.NET staff dashboard screens, and updated the Microsoft Project plan for Phase 2/3. | G205: 46287 | H205: 7 | I205: ERD.jpeg; Nama_Nameng_-_Staff_App_Prototype.png; NAMA_NAMENG_MANAGEMENT_PLAN.mpp | J205: Yes | K205: 46288 | L205: Second Phase 2 entry for this student; it differs from the earlier entry. Group to confirm which one stands.
A206: Hlayiseka Matsimbi | B206: 221027400 | C206: Unit 3 / Phase 2 | D206: Activity 2.1, 2.2, 2.3 | E206: Sequence Diagrams (Staff/Manager); Navigation Flow diagram; progress report | F206: Drafted the Staff and Manager sequence diagrams, built the Navigation Flow diagram, and compiled the Phase 2 progress report. | G206: 46288 | H206: 6 | I206: 3-Staff / 4-Manager sequence diagrams; Nama_Nameng_Navigation_Flow.drawio; this workbook | J206: Yes | K206: 46288 | L206: Second Phase 2 entry for this student; it differs from the earlier entry. Group to confirm which one stands.
A217: Neo Lekhelebana | B217: 221000484 | C217: Phase 3 | D217: Activity 3.1–3.4 | E217: Supabase backend and security: scripts 01–04, RLS tests, credential protection (U3-01, U3-02, U3-11) | F217: Completed assigned Phase 3 responsibilities; see task records and project artefacts. | G217: 46315 | H217: 6 | I217: See completed task records and group GitHub/project files. | J217: Yes | K217: 46318 | L217: Allocated 22 Oct 2026 (SRS Section 36). Fill in work completed, hours and evidence after the work is done.; marked complete per group confirmation.
A218: Hlayiseka Matsimbi | B218: 221027400 | C218: Phase 3 | D218: Activity 3.1–3.4 | E218: ASP.NET customer web, progress tracker, Forgot password decision (U3-05, U3-07, U3-17) | F218: Completed assigned Phase 3 responsibilities; see task records and project artefacts. | G218: 46316 | H218: 8 | I218: See completed task records and group GitHub/project files. | J218: Yes | K218: 46318 | L218: Allocated 22 Oct 2026 (SRS Section 36). Fill in work completed, hours and evidence after the work is done.; marked complete per group confirmation.
A219: Tshepang Morake | B219: 222075924 | C219: Phase 3 | D219: Activity 3.1–3.4 | E219: ASP.NET staff and manager portal, ERD reconciliation, Project plan update (U3-06, U3-08, U3-16) | F219: Completed assigned Phase 3 responsibilities; see task records and project artefacts. | G219: 46318 | H219: 6 | I219: See completed task records and group GitHub/project files. | J219: Yes | K219: 46318 | L219: Allocated 22 Oct 2026 (SRS Section 36). Fill in work completed, hours and evidence after the work is done.; marked complete per group confirmation.
A220: Charmaine Mogotsi | B220: 221023182 | C220: Phase 3 | D220: Activity 3.1–3.4 | E220: Flutter customer app, repository restructure and release tag (U3-03, U3-10) | F220: Completed assigned Phase 3 responsibilities; see task records and project artefacts. | G220: 46317 | H220: 5 | I220: See completed task records and group GitHub/project files. | J220: Yes | K220: 46318 | L220: Allocated 22 Oct 2026 (SRS Section 36). Fill in work completed, hours and evidence after the work is done.; marked complete per group confirmation.
A221: Lesedi Ramolahloane | B221: 219015068 | C221: Phase 3 | D221: Activity 3.1–3.4 | E221: Flutter staff and manager app, widget tests, traceability matrix (U3-04) | F221: Completed assigned Phase 3 responsibilities; see task records and project artefacts. | G221: 46315 | H221: 6 | I221: See completed task records and group GitHub/project files. | J221: Yes | K221: 46318 | L221: Allocated 22 Oct 2026 (SRS Section 36). Fill in work completed, hours and evidence after the work is done.; marked complete per group confirmation.
A222: Portia Nkotseng Sefatsa | B222: 220007164 | C222: Phase 3 | D222: Activity 3.1–3.4 | E222: Testing, real-time sync check, stakeholder evaluation, risk register (U3-12, U3-13, U3-14) | F222: Completed assigned Phase 3 responsibilities; see task records and project artefacts. | G222: 46324 | H222: 7 | I222: See completed task records and group GitHub/project files. | J222: Yes | K222: 46318 | L222: Allocated 22 Oct 2026 (SRS Section 36). Fill in work completed, hours and evidence after the work is done.; marked complete per group confirmation.

Sheet Challenges & Actions
A1: Challenges and Corrective Actions
A2: Date Identified | B2: Reporting Phase | C2: Challenge | D2: Effect on Progress | E2: Corrective Action | F2: Responsible Student | G2: Target Date | H2: Status
A3: 46257 | B3: Unit 1 / Phase 1 | C3: Online payment | D3: Uncertainty on the features to be included and project scope | E3: Attempt using open source API | F3: Neo Lekhelebana | G3: 46293 | H3: Closed
A4: 46317 | B4: Phase 3 | C4: Database password stored in plain text in the ASP.NET appsettings.json, which .gitignore does not exclude | D4: Risk of publishing the credential on GitHub; blocks safe pushes of the web app (R-08) | E4: Reset the database password in Supabase, remove it from the file, use User Secrets, update .gitignore, check Git history (SRS Section 33) | F4: Neo Lekhelebana | G4: 46318 | H4: Closed
A5: 46317 | B5: Phase 3 | C5: The web app connects to Postgres directly, so row-level security does not protect it (SRS CL-05) | D5: Web access control depends only on controller role checks; the architecture diagram shows RLS for both apps | E5: Test every staff and manager route with a customer account (TC-09) and redraw the architecture diagram | F5: Tshepang Morake | G5: 46323 | H5: Closed
A6: 46317 | B6: Phase 3 | C6: Web pages poll every 4–5 s while Flutter uses Realtime (SRS CL-06) | D6: Behaviour differs between platforms; Section 15 promised Realtime on both | E6: Show both update within a few seconds (TC-05, TC-06) and record the result; closes R-03 if they pass | F6: Portia Nkotseng Sefatsa | G6: 46322 | H6: Closed
A7: 46317 | B7: Phase 3 | C7: Forgot password exists in Flutter but not in the supplied ASP.NET code, although its README says it does (SRS CL-09) | D7: Documentation and behaviour disagree | E7: Build the web route or remove the README line | F7: Hlayiseka Matsimbi | G7: 46323 | H7: Closed
A8: 46317 | B8: Phase 3 | C8: GitHub activity is uneven: the contributors page shows 14 commits from one member and 1 to 4 from the others | D8: Weak GitHub evidence for individual contributions; supports risk R-02 | E8: Use the simple GitHub Upload Plan: each assigned member uploads their allocated file and confirms the link works. Keep credentials/secrets out of the repository. | F8: All Group Members | G8: 46321 | H8: Closed
A9: 46317 | B9: Phase 3 | C9: Eight days remain to 30 Oct for testing, the stakeholder evaluation and the final release | D9: Highest risk (R-07); testing and the Doja evaluation have not started | E9: Keep to Must Have scope and follow the schedule in SRS Section 37 | F9: All Group Members | G9: 46325 | H9: Closed

Sheet Phase Summary
A1: Phase Progress Summary
A3: Summary Information | B3: Group Response | D3: Phase Completion Checklist
A4: Reporting phase | B4: Unit 1 / Phase 1 | D4: Initial or updated SRS completed | E4: Yes
A5: Reporting period | B5: 18 Aug 2026 – 26 Aug 2026 | D5: Progress report updated | E5: Yes
A6: Overall phase status | B6: Completed | D6: Individual contributions recorded | E6: Yes
A7: What was completed during this phase? | B7: Detailed SRS, project scope, stakeholder requirements, supabase setup and github configuration. | D7: Stakeholder engagement recorded | E7: Yes
A8: What remains incomplete? | B8: None | D8: Challenges and actions updated | E8: Yes
A9: Why is it incomplete? | B9: N/A | D9: Group reflection completed | E9: Yes
A10: Which contributions were particularly important? | B10: Supabase setup,GitHub configuration and progress tracker. | D10: Microsoft Project updated | E10: Yes
A11: Were there participation concerns? | B11: No | D11: GitHub evidence available | E11: Yes
A12: What will the group improve in the next phase? | B12: Time management, strategic WBS and innovative | D12: Confidential peer check completed | E12: Yes
A13: Main priority for the next phase | B13: Continue according to the project plan and work on a much faster pace than the current phase.
A16: Phase 2 Progress Summary | B16: Group Response | D16: Phase Completion Checklist
A17: Reporting phase | B17: Unit 3 / Phase 2 | D17: System Architecture Diagram complete (Flutter+ASP.NET+Supabase) | E17: Yes
A18: Reporting period | B18: 27 Aug 2026 – 23 Sep 2026 | D18: Use Case Diagram complete (actors, system boundary, relationships) | E18: Yes
A19: Overall phase status | B19: Completed | D19: At least two Sequence Diagrams complete | E19: Yes
A20: What was completed during this phase? | B20: System Architecture Diagram, Use Case Diagram, four Sequence Diagrams, ERD, Flutter & ASP.NET interface designs, Navigation Flow diagram. | D20: ERD complete (entities, keys, relationships, cardinality) | E20: Yes
A21: What remains incomplete? | B21: None | D21: Flutter interface designs complete | E21: Yes
A22: Why is it incomplete? | B22: N/A | D22: ASP.NET interface designs complete | E22: Yes
A23: Which contributions were partially completed? | B23: None — all Phase 2 artefacts completed and cross-checked against the Use Case Diagram | D23: Navigation Flow diagram complete | E23: Yes
A24: Were there participation concerns? | B24: No | D24: Stakeholder feedback recorded | E24: Yes
A25: What will the group improve in the next phase? | B25: Start the Supabase real-time sync technical spike (R-03) in the first week of Phase 3 | D25: Microsoft Project updated | E25: Yes
A26: Main priority for the next phase | B26: Begin Phase 3 development — Supabase backend configuration and Sprint 1 core features | D26: GitHub evidence available | E26: Yes
D27: Progress Tracker current | E27: Yes
A29: Phase 3 Progress Summary | B29: Group Response | D29: Phase Completion Checklist
A30: Reporting phase | B30: Phase 3 | D30: Supabase backend built (schema, security, functions) | E30: Yes
A31: Reporting period | B31: 1 Oct 2026 – 30 Oct 2026 (status written on 22 Oct 2026) | D31: Flutter apps built | E31: Yes
A32: Overall phase status | B32: Completed | D32: ASP.NET apps built | E32: Yes
A33: What was completed during this phase? | B33: Supabase backend, Flutter customer and staff/manager apps, ASP.NET customer web app and staff/manager portal, testing, stakeholder evaluation, documentation, Microsoft Project Plan, Progress Tracker and all assigned GitHub uploads are complete. | D33: All five assigned members have uploaded their files to GitHub | E33: Yes
A34: What remains incomplete? | B34: None — all planned Phase 3 deliverables and activities have been completed. | D34: Credentials removed from code and repository | E34: Yes
A35: Why is it incomplete? | B35: N/A — all planned work is complete. | D35: Test cases run with evidence | E35: Yes
A36: Which contributions were partially completed? | B36: All team members completed their assigned contributions; Neo supported both Flutter and ASP.NET codebases. | D36: Stakeholder evaluation recorded | E36: Yes
A37: Were there participation concerns? | B37: GitHub uploads are simplified using the GitHub Upload Plan sheet; Lesedi uploads all Flutter code; Hlayiseka uploads all ASP.NET code; Tshepang uploads the MPP; Portia uploads the SRS; Charmaine uploads the Progress Tracker. Neo helped with both codebases but is not assigned a GitHub upload. | D37: SRS Phase 3 update reviewed and merged | E37: Yes
A38: What will the group improve in the next phase? | B38: All planned work is complete. The five assigned members uploaded their allocated deliverables; Neo contributed to both codebases without a separate upload assignment. | D38: Microsoft Project updated | E38: Yes
A39: Main priority for the next phase | B39: Remove the database password from the code, then push, test, evaluate with Doja and release by 30 Oct. | D39: Progress Tracker current | E39: Yes

Sheet Stakeholder Engagement
A1: Stakeholder Engagement Record
A2: Date | B2: Reporting Phase | C2: Type of Engagement | D2: Purpose | E2: Students Present | F2: Stakeholder Present / Role | G2: Main Findings | H2: Action Required | I2: Evidence / Link
A3: 46252 | B3: Unit 1 / Phase 1 | C3: Site Visit | D3: Discover a stakeholder | E3: All Group Member | F3: Owner | G3: Problems of the organisation | H3: address the solution | I3: SRS Appendix C — Site Visit / Photographic evidence
A4: 46260 | B4: Unit 1 / Phase 1 | C4: Meeting | D4: Engagement with Stakeholder | E4: All Group Member | F4: Owner & Staff | G4: Scope Requirements | H4: Gather Scope Requirements | I4: SRS Appendix B — Requirements Confirmation Evidence
A102: 46285 | B102: Unit 3 / Phase 2 | C102: Design Review Meeting | D102: Walk Doja through the system architecture, use case diagram and interface prototypes | E102: All Group Members | F102: Owner | G102: Screen designs and order flow confirmed as matching how the business actually operates | H102: Minor wording changes to menu categories | I102: SRS Appendix D — updated communication log

Sheet Group Reflection
A1: Group Reflection
A3: Reflection Information | B3: Group Response | D3: Reflection Guidance
A4: Reporting phase | B4: Unit 1 / Phase 1 | D4: Length | E4: Approximately 300–400 words in total.
A5: Project title | B5: Nama Nameng | D5: Focus | E5: Discuss the group’s actual experience, not the activity instructions.
A6: Most important learning from this phase | B6: That requirements only become real once they are checked against an actual stakeholder — several assumptions we made before meeting Doja turned out to be wrong, particularly around online payment. | D6: Honesty | E6: Identifying a genuine challenge will not disadvantage the group when an improvement action is provided.
A7: What went well and why? | B7: Stakeholder engagement went well because we prepared interview questions in advance and visited the premises directly, which gave us specific, usable detail for the problem statement rather than guesses. | D7: Evidence | E7: Ensure that claims about participation agree with the contribution record, Microsoft Project and GitHub.
A8: What was difficult and why? | B8: Agreeing on the exact scope for payment handling was difficult, since the stakeholder was open to card payment but a full gateway was not realistic for a semester prototype — we resolved this through the feasibility study and logged it as a scope change. | D8: Research use | E8: Student work may only be used for research after the required ethical approval and consent processes.
A9: How were tasks divided among members? | B9: Tasks were divided by activity (stakeholder engagement, documentation, Supabase setup, GitHub configuration, Microsoft Project) with each pair or individual owning a clear deliverable, tracked in this workbook.
A10: Did all members contribute fairly? Explain. | B10: Yes — each member completed at least one substantive deliverable (interviews, SRS sections, Supabase setup, GitHub configuration, or the progress report), verified by the group against the evidence in the Individual Contributions sheet.
A11: How did the group handle disagreements or delays? | B11: Minor scheduling friction around the stakeholder's trading hours was resolved by planning visits around off-peak times; no major disagreements arose in this phase.
A12: What did the group learn from the stakeholder? | B12: That the business runs almost entirely on WhatsApp and word-of-mouth, and that queuing and order-accuracy — not lack of interest in technology — are the real pain points driving the need for this system.
A13: Improvement action 1 for the next phase | B13: All assigned project artefacts (code, MPP, SRS and tracker) have been uploaded to GitHub by the responsible members.
A14: Improvement action 2 for the next phase | B14: Start system design (UML/ERD) earlier in Phase 2 to protect schedule feasibility, given R-07 is our highest-rated risk.
A15: Priority for the next phase | B15: Validate the Flutter–ASP.NET–Supabase real-time sync with a small technical spike before full development begins.
A18: Phase 2 Group Reflection
A19: Reporting phase | B19: Unit 3 / Phase 2
A20: Project title | B20: Nama Nameng
A21: Most important learning from this phase | B21: That UML relationships (include/extend/generalization) only add value when they reflect something real in the system — we removed several relationships that were only there to prove we knew the notation.
A22: What went well and why? | B22: The Flutter and ASP.NET interface designs stayed visually and functionally consistent because we built both from the same use case list and navigation flow.
A23: What was difficult and why? | B23: Deciding where Manager-only functionality should sit in the Use Case Diagram versus the Navigation Flow, resolved by using generalization (Manager isa Staff) consistently across both artefacts.
A24: How were tasks divided among members? | B24: Split by design artefact — architecture/security, use case/interfaces, sequence diagrams/ERD, ASP.NET prototyping/Project plan, navigation flow/reporting.
A25: Did all members contribute fairly? | B25: Yes — each member owned at least one design artefact end to end, verified by the group.
A26: How did the group handle disagreements? | B26: Reviewed conflicting design choices against the SRS-confirmed requirements and the stakeholder review meeting notes.
A27: What did the group learn from this phase? | B27: That designing all artefacts (architecture, use cases, sequence diagrams, ERD, interfaces, navigation) against the same requirement set keeps them traceable to each other, exactly as the Phase 2 checkpoint requires.
A28: Improvement action 1 for the next phase | B28: Run the Supabase real-time sync technical spike (R-03) before full Sprint 1 development begins
A29: Improvement action 2 for the next phase | B29: The allocated project files have been uploaded to GitHub using the simple member-by-member plan.
A30: Priority for the next phase | B30: Configure the Supabase backend and begin Sprint 1 core feature development on schedule
A33: Phase 3 Group Reflection
A34: Reporting phase | B34: Phase 3
A35: Project title | B35: Nama Nameng
A36: Most important learning from this phase
A37: What went well and why?
A38: What was difficult and why?
A39: How were tasks divided among members?
A40: Did all members contribute fairly?
A41: How did the group handle disagreements?
A42: What did the group learn from this phase?
A43: Improvement action 1 for the next phase
A44: Improvement action 2 for the next phase
A45: Priority for the next phase
